Traceback (most recent call last):
  File "/usr/share/miniconda3/envs/computo/lib/python3.9/site-packages/nbclient/client.py", line 778, in _async_poll_for_reply
    msg = await ensure_async(self.kc.shell_channel.get_msg(timeout=new_timeout))
  File "/usr/share/miniconda3/envs/computo/lib/python3.9/site-packages/jupyter_core/utils/__init__.py", line 184, in ensure_async
    result = await obj
  File "/usr/share/miniconda3/envs/computo/lib/python3.9/site-packages/jupyter_client/channels.py", line 315, in get_msg
    raise Empty
_queue.Empty

During handling of the above exception, another exception occurred:

Traceback (most recent call last):
  File "/usr/share/miniconda3/envs/computo/lib/python3.9/site-packages/jupyter_cache/executors/utils.py", line 58, in single_nb_execution
    executenb(
  File "/usr/share/miniconda3/envs/computo/lib/python3.9/site-packages/nbclient/client.py", line 1305, in execute
    return NotebookClient(nb=nb, resources=resources, km=km, **kwargs).execute()
  File "/usr/share/miniconda3/envs/computo/lib/python3.9/site-packages/jupyter_core/utils/__init__.py", line 168, in wrapped
    return loop.run_until_complete(inner)
  File "/usr/share/miniconda3/envs/computo/lib/python3.9/asyncio/base_events.py", line 647, in run_until_complete
    return future.result()
  File "/usr/share/miniconda3/envs/computo/lib/python3.9/site-packages/nbclient/client.py", line 705, in async_execute
    await self.async_execute_cell(
  File "/usr/share/miniconda3/envs/computo/lib/python3.9/site-packages/nbclient/client.py", line 1001, in async_execute_cell
    exec_reply = await self.task_poll_for_reply
  File "/usr/share/miniconda3/envs/computo/lib/python3.9/site-packages/nbclient/client.py", line 802, in _async_poll_for_reply
    error_on_timeout_execute_reply = await self._async_handle_timeout(timeout, cell)
  File "/usr/share/miniconda3/envs/computo/lib/python3.9/site-packages/nbclient/client.py", line 852, in _async_handle_timeout
    raise CellTimeoutError.error_from_timeout_and_cell(
nbclient.exceptions.CellTimeoutError: A cell timed out while it was being executed, after 30 seconds.
The message was: Cell execution timed out.
Here is a preview of the cell contents:
-------------------
['N = 50', 'observations = 2000', '', 'df_1cell = dataframe_1cell(N, observations)', "df_1cell['R1'] = list(4*np.pi*df_1cell.A1/(df_1cell.P1)**2)"]
...
["ddf_5cells['R4'] = list(4*np.pi*ddf_5cells.A4/(ddf_5cells.P4)**2)", "ddf_5cells['R5'] = list(4*np.pi*ddf_5cells.A5/(ddf_5cells.P5)**2)", "ddf_5cells = ddf_5cells[['A1', 'P1', 'R1', 'A2', 'P2', 'R2', 'A3', 'P3', 'R3', 'A4', 'P4', 'R4', 'A5', 'P5', 'R5', 'process']]", '', 'ddf_5cells.head()']
-------------------

